<mujocoinclude>
    <body name="panda_link0" childclass="panda" >
        <geom class="panda_viz" mesh="link0_viz"/>
        <geom class="panda_col" mesh="link0_col" mass="2.91242"/>
        <body name="panda_link1" pos="0 0 0.333">
            <joint name="panda_joint1" range="-2.8973 2.8973" class="panda_arm"/>
            <geom class="panda_viz" mesh="link1_viz"/>
            <geom class="panda_col" mesh="link1_col" mass="2.7063"/>
            <body name="panda_link2" pos="0 0 0" quat="0.707107 -0.707107 0 0">
                <joint name="panda_joint2" range="-1.7628 1.7628" class="panda_arm"/>
                <geom class="panda_viz" mesh="link2_viz"/>
                <geom class="panda_col" mesh="link2_col" mass="2.73046"/>
                <body name="panda_link3" pos="0 -0.316 0" quat="0.707107 0.707107 0 0">
                    <joint name="panda_joint3" range="-2.8973 2.8973" class="panda_arm"/>
                    <geom class="panda_viz" mesh="link3_viz"/>
                    <geom class="panda_grey_viz" mesh="link3_dark_viz" pos="0 .001 0"/>
                    <geom class="panda_col" mesh="link3_col" mass="2.04104"/>
                    <body name="panda_link4" pos="0.0825 0 0" quat="0.707107 0.707107 0 0">
                        <joint name="panda_joint4" range="-3.0718 -0.4" class="panda_arm"/>
                        <geom class="panda_viz" mesh="link4_viz"/>
                        <geom class="panda_grey_viz" mesh="link4_dark_viz"/>
                        <geom class="panda_col" mesh="link4_col" mass="2.08129"/>
                        <body name="panda_link5" pos="-0.0825 0.384 0" quat="0.707107 -0.707107 0 0">
                            <joint name="panda_joint5" range="-2.8973 2.8973" class="panda_forearm"/>
                            <geom class="panda_viz" mesh="link5_viz"/>
                            <geom class="panda_grey_viz" mesh="link5_dark_viz"/>
                            <geom class="panda_col" mesh="link5_col" mass="3.00049"/>
                            <body name="panda_link6" pos="0 0 0" euler='1.57 0 1.57'>
                                <joint name="panda_joint6" range="-1.6573 2.1127" class="panda_forearm"/>
                                <!-- <body name="panda_link6" pos="0 0 0" quat="0.707107 0.707107 0 0"> -->
                                <!-- <joint name="panda_joint6" range="-0.0873 3.8223" class="panda_forearm"/> -->
                                <geom class="panda_viz" mesh="link6_viz"/>
                                <geom class="panda_grey_viz" mesh="link6_dark_viz"/>
                                <geom class="panda_col" mesh="link6_col" mass="1.3235"/>
                                <body name="panda_link7" pos="0.088 0 0" euler='1.57 0 0.7854'>
                                    <joint name="panda_joint7" range="-2.8973 2.8973" class="panda_forearm"/>
                                    <!-- <body name="panda_link7" pos="0.088 0 0" quat="0.707107 0.707107 0 0"> -->
                                    <!-- <joint name="panda_joint7" range="-2.9671 2.9671" class="panda_forearm"/> -->
                                    <geom class="panda_viz" mesh="link7_viz" rgba=".8 .8 .82 1"/>
                                    <geom class="panda_grey_viz" mesh="link7_dark_viz" pos="0 0 -.0008"/>
                                    <geom class="panda_col" mesh="link7_col" mass="0.2"/>
                                    <camera name="Franka_wrist_cam" pos=".050 -.050 0.15" euler="2.95 0.2 -.787"/>

                                    <!-- End Effector -->
                                    <body name="panda_gripper">
                                       <include file = "gripper.xml" />
                                       <body name="end_effector_grasp" pos="0 0 0.24">
                                        <site name='end_effector_grasp' pos='0 0 0' size='0.001'/>
                                       </body>
                                       <body name="end_effector" pos="0 0 0.29">
                                        <site name='end_effector' pos='0 0 0' size='0.001'/>
                                       </body>
                                    </body>
                                </body>
                            </body>
                        </body>
                    </body>
                </body>
            </body>
        </body>
    </body>
</mujocoinclude>
